Workbook

Sheet Read Me
B2: Cattle Fattening TMR Management Workbook
B3: 100-Day TMR Based Fattening Program — Jahangir (v2 — expanded)
B5: What this workbook does
C6: Ye Sultan Dairy ka poora Farm Management System hai — Fattening, Qurbani, Dairy, aur Breeding, sath hi Inventory, Staff aur Accounts, sab ek hi interconnected Excel file mein. Sab sheets aapas mein linked hain — ek jagah number badlein to poori file khud update ho jati hai.
B8: Color legend (har sheet mein)
C9: Blue text = aapko yahan number/rate daalna hai (hardcoded input)
C10: Yellow fill = ye cell zaroor fill karein (rate, weight, date waghera)
C11: Black text = formula hai, ise edit na karein
C12: Green text = doosri sheet se link hai
B14: Sheet order aur kya karna hai
B15: FOUNDATION
B16: 1. Ingredient Database | C16: 56 ingredients — Rate per kg (column J) yahan daalein.
B17: 2. Ration Formulator | C17: Concentrate aur Roughage Mix dropdown se banate hain, jitne chahein ingredients.
B18: 3. Animal Register | C18: Ek hi register — Fattening, Qurbani, Dairy, Breeding Stock sab. Purpose column se pehchana jata hai.
B19: 4. Animal Profile | C19: Kisi bhi Animal ID ko dropdown se chunein — poora record ek jagah dikh jata hai.
B20: QURBANI
B21: 5. Qurbani Module | C21: Qurbani animals khud yahan aa jate hain. Sale/Invoice Log (side mein) bharein to Profit/Loss khud nikalta hai.
B22: DAIRY
B23: 6. Dairy Module | C23: Dairy animals khud yahan aa jate hain, milk average ke sath.
B24: 7. Milk Production Log | C24: Roz ki milking (morning/evening) yahan likhein.
B25: 8. Milk Customers | C25: Doodh ke regular customers aur unki daily order/rate.
B26: BREEDING
B27: 9. Breeding Module | C27: Breeding Stock animals khud yahan aa jate hain, latest breeding status ke sath.
B28: 10. Breeding Log | C28: Har breeding event — Expected Calving Date khud +283 din calculate hoti hai.
B29: 11. Calving Log | C29: Naya calf paida hote hi yahan likhein, phir Animal Register mein bhi register karein.
B30: 12. Weaning Log | C30: Calf ki weaning date aur weight.
B31: FATTENING (roz ka kaam)
B32: 13. Daily Feeding | C32: Roz Animal ID aur current weight daalein — feed quantity aur energy khud calculate hoti hai.
B33: 14. Weight Log | C33: Har weighing (daily/weekly/fortnightly) yahan record karein — kabhi delete na karein.
B34: 15. Weight & Growth Tracker | C34: Har animal ka latest weight, gain, ADG ek nazar mein.
B35: 16. Health Log | C35: Vaccination, deworming, treatment — ek animal ya ek sath kai animals.
B36: 17. Feed Purchase Log | C36: Ingredient khareedte waqt yahan likhein — Feed Stock khud update hota hai.
B37: 18. Cost Tracker | C37: Roz jo ingredient use hua uski quantity — cost khud calculate hota hai.
B38: 19. Feed Stock | C38: Godam ka stock, kam hone par alert.
B39: INVENTORY, STAFF, ACCOUNTS
B40: 20. General Inventory | C40: Medicines, dairy equipment, farm tools.
B41: 21. Fattening Customers | C41: Fattened cattle ke buyers (butchers/wholesalers).
B42: 22. Fattening Sales Log | C42: Jab Fattening animal bike, yahan likhein — Profit/Loss khud nikalta hai.
B43: 23. Staff Module | C43: Har mulazim ki details aur salary.
B44: 24. Salary Payments | C44: Har mahine ki salary payment yahan likhein.
...

Sheet Dashboard
A1: FATTENING PROGRAM DASHBOARD
A2: 100-Day TMR Fattening Program — Live Summary
A4: LIVE OPERATIONS SUMMARY
A5: ACTIVE ANIMALS | C5: AVG DAYS ON FEED | E5: AVG DAYS REMAINING | G5: FEED STOCK ALERTS
A6: =COUNTIF('Animal Register'!Q:Q,"Active") -> 1 | C6: =IF(COUNTIF('Animal Register'!Q:Q,"Active")=0,"-",ROUND(AVERAGEIF('Animal Register'!Q:Q,"Active",'Animal Register'!O:O),0)) -> 9 | E6: =IF(ISNUMBER(C6),100-C6,"-") -> 91 | G6: =COUNTIF('Feed Stock'!G:G,"Reorder Now") -> 0
A8: AVG START WEIGHT (kg) | C8: AVG CURRENT WEIGHT (kg) | E8: AVG GAIN SO FAR (kg) | G8: TOTAL FEED COST (Rs)
A9: =IF(COUNTIF('Animal Register'!Q:Q,"Active")=0,"-",ROUND(AVERAGEIF('Animal Register'!Q:Q,"Active",'Animal Register'!I:I),1)) -> 212 | C9: =IF(COUNTIF('Animal Register'!Q:Q,"Active")=0,"-",ROUND(AVERAGEIF('Animal Register'!Q:Q,"Active",'Animal Register'!S:S),1)) -> 212 | E9: =IF(AND(ISNUMBER(A9),ISNUMBER(C9)),ROUND(C9-A9,1),"-") -> 0 | G9: ='Cost Tracker'!J4 -> 0
A11: FCR (kg DM feed / kg gain) | C11: COST PER KG GAIN (Rs) | E11: AVG BCS (LATEST) | G11: ANIMALS SOLD
A12: =IF(SUM('Weight & Growth Tracker'!I5:I74)=0,"-",ROUND(SUM('Daily Feeding'!F5:F104)/SUM('Weight & Growth Tracker'!I5:I74),2)) -> - | C12: =IF(SUM('Weight & Growth Tracker'!I5:I74)=0,"-",ROUND('Cost Tracker'!J4/SUM('Weight & Growth Tracker'!I5:I74),0)) -> - | E12: =IFERROR(ROUND(AVERAGEIF('Weight & Growth Tracker'!G5:G74,"<>-"),1),"-") -> 2.5 | G12: =COUNTIF('Animal Register'!Q:Q,"Sold") -> 0
A15: PLANNING TARGET (Editable — based on 58% dressing practice)
A16: Target Final Live Weight (kg) | D16: Dressing % | F16: Expected Meat Output (kg)
A17: 328 | D17: 0.58 | F17: =IF(AND(ISNUMBER(A17),ISNUMBER(D17)),ROUND(A17*D17,1),"-") -> 190.2
K21: Chart data (auto — do not edit)
K22: Stage | L22: Weight (kg)
K23: Start | L23: =A9 -> 212
K24: Current | L24: =C9 -> 212
K25: Target Final | L25: =A17 -> 328

Sheet Ingredient Database
A1: INGREDIENT MASTER DATABASE (DM basis for CP / TDN / Energy / NDF)
A3: ID | B3: Ingredient Name | C3: Category | D3: Sub-Category | E3: DM % | F3: CP % | G3: TDN % | H3: Energy - ME (Mcal/kg) | I3: NDF (Fiber) % | J3: Rate per kg (Rs)
A4: 1 | B4: Maize Grain (Crushed) | C4: Concentrate | D4: Grain | E4: 0.88 | F4: 0.09 | G4: 0.82 | H4: =IF($D4="Dry Straw/Stover",$G4*2.65,IF($C4="Roughage",$G4*3.31,$G4*3.62)) -> 2.9684 | I4: 0.1
A5: 2 | B5: Wheat Grain (Crushed) | C5: Concentrate | D5: Grain | E5: 0.88 | F5: 0.12 | G5: 0.82 | H5: =IF($D5="Dry Straw/Stover",$G5*2.65,IF($C5="Roughage",$G5*3.31,$G5*3.62)) -> 2.9684 | I5: 0.12
A6: 3 | B6: Barley Grain (Crushed) | C6: Concentrate | D6: Grain | E6: 0.88 | F6: 0.115 | G6: 0.75 | H6: =IF($D6="Dry Straw/Stover",$G6*2.65,IF($C6="Roughage",$G6*3.31,$G6*3.62)) -> 2.715 | I6: 0.18
A7: 4 | B7: Sorghum Grain (Jowar) | C7: Concentrate | D7: Grain | E7: 0.88 | F7: 0.1 | G7: 0.78 | H7: =IF($D7="Dry Straw/Stover",$G7*2.65,IF($C7="Roughage",$G7*3.31,$G7*3.62)) -> 2.8236 | I7: 0.12
A8: 5 | B8: Pearl Millet Grain (Bajra) | C8: Concentrate | D8: Grain | E8: 0.88 | F8: 0.115 | G8: 0.75 | H8: =IF($D8="Dry Straw/Stover",$G8*2.65,IF($C8="Roughage",$G8*3.31,$G8*3.62)) -> 2.715 | I8: 0.15
A9: 6 | B9: Broken Rice (Rice Kani) | C9: Concentrate | D9: Grain | E9: 0.88 | F9: 0.08 | G9: 0.8 | H9: =IF($D9="Dry Straw/Stover",$G9*2.65,IF($C9="Roughage",$G9*3.31,$G9*3.62)) -> 2.896 | I9: 0.08
A10: 7 | B10: Cottonseed Cake (Banaula Khal) | C10: Concentrate | D10: Oilseed Cake | E10: 0.9 | F10: 0.22 | G10: 0.68 | H10: =IF($D10="Dry Straw/Stover",$G10*2.65,IF($C10="Roughage",$G10*3.31,$G10*3.62)) -> 2.4616 | I10: 0.35
A11: 8 | B11: Cottonseed Meal (Solvent Extracted) | C11: Concentrate | D11: Oilseed Cake | E11: 0.9 | F11: 0.28 | G11: 0.65 | H11: =IF($D11="Dry Straw/Stover",$G11*2.65,IF($C11="Roughage",$G11*3.31,$G11*3.62)) -> 2.353 | I11: 0.3
A12: 9 | B12: Canola / Sarson Cake | C12: Concentrate | D12: Oilseed Cake | E12: 0.9 | F12: 0.36 | G12: 0.7 | H12: =IF($D12="Dry Straw/Stover",$G12*2.65,IF($C12="Roughage",$G12*3.31,$G12*3.62)) -> 2.534 | I12: 0.25
A13: 10 | B13: Sunflower Cake | C13: Concentrate | D13: Oilseed Cake | E13: 0.9 | F13: 0.3 | G13: 0.65 | H13: =IF($D13="Dry Straw/Stover",$G13*2.65,IF($C13="Roughage",$G13*3.31,$G13*3.62)) -> 2.353 | I13: 0.38
A14: 11 | B14: Sunflower Meal (Decorticated) | C14: Concentrate | D14: Oilseed Cake | E14: 0.9 | F14: 0.36 | G14: 0.68 | H14: =IF($D14="Dry Straw/Stover",$G14*2.65,IF($C14="Roughage",$G14*3.31,$G14*3.62)) -> 2.4616 | I14: 0.28
A15: 12 | B15: Soybean Meal | C15: Concentrate | D15: Oilseed Cake | E15: 0.89 | F15: 0.46 | G15: 0.82 | H15: =IF($D15="Dry Straw/Stover",$G15*2.65,IF($C15="Roughage",$G15*3.31,$G15*3.62)) -> 2.9684 | I15: 0.12
... A59: 56 | B59: Sugarcane Bagasse | C59: Roughage | D59: Dry Straw/Stover | E59: 0.9 | F59: 0.02 | G59: 0.35 | H59: =IF($D59="Dry Straw/Stover",$G59*2.65,IF($C59="Roughage",$G59*3.31,$G59*3.62)) -> 0.9275 | I59: 0.85

Sheet Ration Formulator
A1: RATION FORMULATOR
A3: A) PHASE REFERENCE — Day Range & Concentrate:Roughage Ratio
A4: Phase | B4: Day From | C4: Day To | D4: Concentrate % (of DM) | E4: Roughage % (of DM)
A5: Phase 1 - Adaptation | B5: 1 | C5: 33 | D5: 0.45 | E5: 0.55
A6: Phase 2 - Growth | B6: 34 | C6: 66 | D6: 0.6 | E6: 0.4
A7: Phase 3 - Finishing | B7: 67 | C7: 100 | D7: 0.75 | E7: 0.25
A9: B) CONCENTRATE MIX — Blend Composition (constant across all phases, dropdown se chunein)
A10: Ingredient (dropdown) | B10: % Inclusion in Mix | C10: CP Contribution | D10: TDN Contribution | E10: DM Contribution | F10: Energy Contribution (Mcal)
A11: Maize Grain (Crushed) | B11: 0.25 | C11: =IF($A11="",0,$B11*IFERROR(INDEX('Ingredient Database'!$F:$F,MATCH($A11,'Ingredient Database'!$B:$B,0)),0)) -> 0.0225 | D11: =IF($A11="",0,$B11*IFERROR(INDEX('Ingredient Database'!$G:$G,MATCH($A11,'Ingredient Database'!$B:$B,0)),0)) -> 0.205 | E11: =IF($A11="",0,$B11*IFERROR(INDEX('Ingredient Database'!$E:$E,MATCH($A11,'Ingredient Database'!$B:$B,0)),0)) -> 0.22 | F11: =IF($A11="",0,$B11*IFERROR(INDEX('Ingredient Database'!$H:$H,MATCH($A11,'Ingredient Database'!$B:$B,0)),0)) -> 0.7421
A12: Wheat Bran (Chokar) | B12: 0.12 | C12: =IF($A12="",0,$B12*IFERROR(INDEX('Ingredient Database'!$F:$F,MATCH($A12,'Ingredient Database'!$B:$B,0)),0)) -> 0.018 | D12: =IF($A12="",0,$B12*IFERROR(INDEX('Ingredient Database'!$G:$G,MATCH($A12,'Ingredient Database'!$B:$B,0)),0)) -> 0.0816 | E12: =IF($A12="",0,$B12*IFERROR(INDEX('Ingredient Database'!$E:$E,MATCH($A12,'Ingredient Database'!$B:$B,0)),0)) -> 0.1056 | F12: =IF($A12="",0,$B12*IFERROR(INDEX('Ingredient Database'!$H:$H,MATCH($A12,'Ingredient Database'!$B:$B,0)),0)) -> 0.295392
A13: Cottonseed Cake (Banaula Khal) | B13: 0.25 | C13: =IF($A13="",0,$B13*IFERROR(INDEX('Ingredient Database'!$F:$F,MATCH($A13,'Ingredient Database'!$B:$B,0)),0)) -> 0.055 | D13: =IF($A13="",0,$B13*IFERROR(INDEX('Ingredient Database'!$G:$G,MATCH($A13,'Ingredient Database'!$B:$B,0)),0)) -> 0.17 | E13: =IF($A13="",0,$B13*IFERROR(INDEX('Ingredient Database'!$E:$E,MATCH($A13,'Ingredient Database'!$B:$B,0)),0)) -> 0.225 | F13: =IF($A13="",0,$B13*IFERROR(INDEX('Ingredient Database'!$H:$H,MATCH($A13,'Ingredient Database'!$B:$B,0)),0)) -> 0.6154
A14: Canola / Sarson Cake | B14: 0.15 | C14: =IF($A14="",0,$B14*IFERROR(INDEX('Ingredient Database'!$F:$F,MATCH($A14,'Ingredient Database'!$B:$B,0)),0)) -> 0.054 | D14: =IF($A14="",0,$B14*IFERROR(INDEX('Ingredient Database'!$G:$G,MATCH($A14,'Ingredient Database'!$B:$B,0)),0)) -> 0.105 | E14: =IF($A14="",0,$B14*IFERROR(INDEX('Ingredient Database'!$E:$E,MATCH($A14,'Ingredient Database'!$B:$B,0)),0)) -> 0.135 | F14: =IF($A14="",0,$B14*IFERROR(INDEX('Ingredient Database'!$H:$H,MATCH($A14,'Ingredient Database'!$B:$B,0)),0)) -> 0.3801
A15: Rice Polish | B15: 0.1 | C15: =IF($A15="",0,$B15*IFERROR(INDEX('Ingredient Database'!$F:$F,MATCH($A15,'Ingredient Database'!$B:$B,0)),0)) -> 0.0125 | D15: =IF($A15="",0,$B15*IFERROR(INDEX('Ingredient Database'!$G:$G,MATCH($A15,'Ingredient Database'!$B:$B,0)),0)) -> 0.072 | E15: =IF($A15="",0,$B15*IFERROR(INDEX('Ingredient Database'!$E:$E,MATCH($A15,'Ingredient Database'!$B:$B,0)),0)) -> 0.09 | F15: =IF($A15="",0,$B15*IFERROR(INDEX('Ingredient Database'!$H:$H,MATCH($A15,'Ingredient Database'!$B:$B,0)),0)) -> 0.26064
A16: Molasses (Shakar) | B16: 0.08 | C16: =IF($A16="",0,$B16*IFERROR(INDEX('Ingredient Database'!$F:$F,MATCH($A16,'Ingredient Database'!$B:$B,0)),0)) -> 0.0032 | D16: =IF($A16="",0,$B16*IFERROR(INDEX('Ingredient Database'!$G:$G,MATCH($A16,'Ingredient Database'!$B:$B,0)),0)) -> 0.0576 | E16: =IF($A16="",0,$B16*IFERROR(INDEX('Ingredient Database'!$E:$E,MATCH($A16,'Ingredient Database'!$B:$B,0)),0)) -> 0.06 | F16: =IF($A16="",0,$B16*IFERROR(INDEX('Ingredient Database'!$H:$H,MATCH($A16,'Ingredient Database'!$B:$B,0)),0)) -> 0.208512
A17: Mineral Mixture | B17: 0.03 | C17: =IF($A17="",0,$B17*IFERROR(INDEX('Ingredient Database'!$F:$F,MATCH($A17,'Ingredient Database'!$B:$B,0)),0)) -> 0 | D17: =IF($A17="",0,$B17*IFERROR(INDEX('Ingredient Database'!$G:$G,MATCH($A17,'Ingredient Database'!$B:$B,0)),0)) -> 0 | E17: =IF($A17="",0,$B17*IFERROR(INDEX('Ingredient Database'!$E:$E,MATCH($A17,'Ingredient Database'!$B:$B,0)),0)) -> 0.0294 | F17: =IF($A17="",0,$B17*IFERROR(INDEX('Ingredient Database'!$H:$H,MATCH($A17,'Ingredient Database'!$B:$B,0)),0)) -> 0
A18: Salt | B18: 0.02 | C18: =IF($A18="",0,$B18*IFERROR(INDEX('Ingredient Database'!$F:$F,MATCH($A18,'Ingredient Database'!$B:$B,0)),0)) -> 0 | D18: =IF($A18="",0,$B18*IFERROR(INDEX('Ingredient Database'!$G:$G,MATCH($A18,'Ingredient Database'!$B:$B,0)),0)) -> 0 | E18: =IF($A18="",0,$B18*IFERROR(INDEX('Ingredient Database'!$E:$E,MATCH($A18,'Ingredient Database'!$B:$B,0)),0)) -> 0.0198 | F18: =IF($A18="",0,$B18*IFERROR(INDEX('Ingredient Database'!$H:$H,MATCH($A18,'Ingredient Database'!$B:$B,0)),0)) -> 0
C19: =IF($A19="",0,$B19*IFERROR(INDEX('Ingredient Database'!$F:$F,MATCH($A19,'Ingredient Database'!$B:$B,0)),0)) -> 0 | D19: =IF($A19="",0,$B19*IFERROR(INDEX('Ingredient Database'!$G:$G,MATCH($A19,'Ingredient Database'!$B:$B,0)),0)) -> 0 | E19: =IF($A19="",0,$B19*IFERROR(INDEX('Ingredient Database'!$E:$E,MATCH($A19,'Ingredient Database'!$B:$B,0)),0)) -> 0 | F19: =IF($A19="",0,$B19*IFERROR(INDEX('Ingredient Database'!$H:$H,MATCH($A19,'Ingredient Database'!$B:$B,0)),0)) -> 0
C20: =IF($A20="",0,$B20*IFERROR(INDEX('Ingredient Database'!$F:$F,MATCH($A20,'Ingredient Database'!$B:$B,0)),0)) -> 0 | D20: =IF($A20="",0,$B20*IFERROR(INDEX('Ingredient Database'!$G:$G,MATCH($A20,'Ingredient Database'!$B:$B,0)),0)) -> 0 | E20: =IF($A20="",0,$B20*IFERROR(INDEX('Ingredient Database'!$E:$E,MATCH($A20,'Ingredient Database'!$B:$B,0)),0)) -> 0 | F20: =IF($A20="",0,$B20*IFERROR(INDEX('Ingredient Database'!$H:$H,MATCH($A20,'Ingredient Database'!$B:$B,0)),0)) -> 0
A21: TOTAL / BLEND VALUE | B21: =SUM(B11:B20) -> 1 | C21: =SUM(C11:C20) -> 0.1652 | D21: =SUM(D11:D20) -> 0.6912 | E21: =SUM(E11:E20) -> 0.8848 | F21: =SUM(F11:F20) -> 2.502144
A23: C) ROUGHAGE MIX — Flexible Blend per Phase (dropdown se jitne chahein ingredients mix karein)
A24: Phase 1 - Adaptation
A25: Ingredient (dropdown) | B25: % of Total Roughage | C25: CP Contribution | D25: TDN Contribution | E25: DM Contribution | F25: Energy Contribution (Mcal)
A26: Maize Silage | B26: 0.5 | C26: =IF($A26="",0,$B26*IFERROR(INDEX('Ingredient Database'!$F:$F,MATCH($A26,'Ingredient Database'!$B:$B,0)),0)) -> 0.04 | D26: =IF($A26="",0,$B26*IFERROR(INDEX('Ingredient Database'!$G:$G,MATCH($A26,'Ingredient Database'!$B:$B,0)),0)) -> 0.34 | E26: =IF($A26="",0,$B26*IFERROR(INDEX('Ingredient Database'!$E:$E,MATCH($A26,'Ingredient Database'!$B:$B,0)),0)) -> 0.16 | F26: =IF($A26="",0,$B26*IFERROR(INDEX('Ingredient Database'!$H:$H,MATCH($A26,'Ingredient Database'!$B:$B,0)),0)) -> 1.1254
A27: Wheat Straw (Bhoosa) | B27: 0.5 | C27: =IF($A27="",0,$B27*IFERROR(INDEX('Ingredient Database'!$F:$F,MATCH($A27,'Ingredient Database'!$B:$B,0)),0)) -> 0.02 | D27: =IF($A27="",0,$B27*IFERROR(INDEX('Ingredient Database'!$G:$G,MATCH($A27,'Ingredient Database'!$B:$B,0)),0)) -> 0.21 | E27: =IF($A27="",0,$B27*IFERROR(INDEX('Ingredient Database'!$E:$E,MATCH($A27,'Ingredient Database'!$B:$B,0)),0)) -> 0.45 | F27: =IF($A27="",0,$B27*IFERROR(INDEX('Ingredient Database'!$H:$H,MATCH($A27,'Ingredient Database'!$B:$B,0)),0)) -> 0.5565
C28: =IF($A28="",0,$B28*IFERROR(INDEX('Ingredient Database'!$F:$F,MATCH($A28,'Ingredient Database'!$B:$B,0)),0)) -> 0 | D28: =IF($A28="",0,$B28*IFERROR(INDEX('Ingredient Database'!$G:$G,MATCH($A28,'Ingredient Database'!$B:$B,0)),0)) -> 0 | E28: =IF($A28="",0,$B28*IFERROR(INDEX('Ingredient Database'!$E:$E,MATCH($A28,'Ingredient Database'!$B:$B,0)),0)) -> 0 | F28: =IF($A28="",0,$B28*IFERROR(INDEX('Ingredient Database'!$H:$H,MATCH($A28,'Ingredient Database'!$B:$B,0)),0)) -> 0
C29: =IF($A29="",0,$B29*IFERROR(INDEX('Ingredient Database'!$F:$F,MATCH($A29,'Ingredient Database'!$B:$B,0)),0)) -> 0 | D29: =IF($A29="",0,$B29*IFERROR(INDEX('Ingredient Database'!$G:$G,MATCH($A29,'Ingredient Database'!$B:$B,0)),0)) -> 0 | E29: =IF($A29="",0,$B29*IFERROR(INDEX('Ingredient Database'!$E:$E,MATCH($A29,'Ingredient Database'!$B:$B,0)),0)) -> 0 | F29: =IF($A29="",0,$B29*IFERROR(INDEX('Ingredient Database'!$H:$H,MATCH($A29,'Ingredient Database'!$B:$B,0)),0)) -> 0
C30: =IF($A30="",0,$B30*IFERROR(INDEX('Ingredient Database'!$F:$F,MATCH($A30,'Ingredient Database'!$B:$B,0)),0)) -> 0 | D30: =IF($A30="",0,$B30*IFERROR(INDEX('Ingredient Database'!$G:$G,MATCH($A30,'Ingredient Database'!$B:$B,0)),0)) -> 0 | E30: =IF($A30="",0,$B30*IFERROR(INDEX('Ingredient Database'!$E:$E,MATCH($A30,'Ingredient Database'!$B:$B,0)),0)) -> 0 | F30: =IF($A30="",0,$B30*IFERROR(INDEX('Ingredient Database'!$H:$H,MATCH($A30,'Ingredient Database'!$B:$B,0)),0)) -> 0
C31: =IF($A31="",0,$B31*IFERROR(INDEX('Ingredient Database'!$F:$F,MATCH($A31,'Ingredient Database'!$B:$B,0)),0)) -> 0 | D31: =IF($A31="",0,$B31*IFERROR(INDEX('Ingredient Database'!$G:$G,MATCH($A31,'Ingredient Database'!$B:$B,0)),0)) -> 0 | E31: =IF($A31="",0,$B31*IFERROR(INDEX('Ingredient Database'!$E:$E,MATCH($A31,'Ingredient Database'!$B:$B,0)),0)) -> 0 | F31: =IF($A31="",0,$B31*IFERROR(INDEX('Ingredient Database'!$H:$H,MATCH($A31,'Ingredient Database'!$B:$B,0)),0)) -> 0
A32: TOTAL | B32: =SUM(B26:B31) -> 1 | C32: =SUM(C26:C31) -> 0.06 | D32: =SUM(D26:D31) -> 0.55 | E32: =SUM(E26:E31) -> 0.61 | F32: =SUM(F26:F31) -> 1.6819
A34: Phase 2 - Growth
A35: Ingredient (dropdown) | B35: % of Total Roughage | C35: CP Contribution | D35: TDN Contribution | E35: DM Contribution | F35: Energy Contribution (Mcal)
A36: Maize Silage | B36: 0.65 | C36: =IF($A36="",0,$B36*IFERROR(INDEX('Ingredient Database'!$F:$F,MATCH($A36,'Ingredient Database'!$B:$B,0)),0)) -> 0.052 | D36: =IF($A36="",0,$B36*IFERROR(INDEX('Ingredient Database'!$G:$G,MATCH($A36,'Ingredient Database'!$B:$B,0)),0)) -> 0.442 | E36: =IF($A36="",0,$B36*IFERROR(INDEX('Ingredient Database'!$E:$E,MATCH($A36,'Ingredient Database'!$B:$B,0)),0)) -> 0.208 | F36: =IF($A36="",0,$B36*IFERROR(INDEX('Ingredient Database'!$H:$H,MATCH($A36,'Ingredient Database'!$B:$B,0)),0)) -> 1.46302
A37: Wheat Straw (Bhoosa) | B37: 0.35 | C37: =IF($A37="",0,$B37*IFERROR(INDEX('Ingredient Database'!$F:$F,MATCH($A37,'Ingredient Database'!$B:$B,0)),0)) -> 0.014 | D37: =IF($A37="",0,$B37*IFERROR(INDEX('Ingredient Database'!$G:$G,MATCH($A37,'Ingredient Database'!$B:$B,0)),0)) -> 0.147 | E37: =IF($A37="",0,$B37*IFERROR(INDEX('Ingredient Database'!$E:$E,MATCH($A37,'Ingredient Database'!$B:$B,0)),0)) -> 0.315 | F37: =IF($A37="",0,$B37*IFERROR(INDEX('Ingredient Database'!$H:$H,MATCH($A37,'Ingredient Database'!$B:$B,0)),0)) -> 0.38955
C38: =IF($A38="",0,$B38*IFERROR(INDEX('Ingredient Database'!$F:$F,MATCH($A38,'Ingredient Database'!$B:$B,0)),0)) -> 0 | D38: =IF($A38="",0,$B38*IFERROR(INDEX('Ingredient Database'!$G:$G,MATCH($A38,'Ingredient Database'!$B:$B,0)),0)) -> 0 | E38: =IF($A38="",0,$B38*IFERROR(INDEX('Ingredient Database'!$E:$E,MATCH($A38,'Ingredient Database'!$B:$B,0)),0)) -> 0 | F38: =IF($A38="",0,$B38*IFERROR(INDEX('Ingredient Database'!$H:$H,MATCH($A38,'Ingredient Database'!$B:$B,0)),0)) -> 0
C39: =IF($A39="",0,$B39*IFERROR(INDEX('Ingredient Database'!$F:$F,MATCH($A39,'Ingredient Database'!$B:$B,0)),0)) -> 0 | D39: =IF($A39="",0,$B39*IFERROR(INDEX('Ingredient Database'!$G:$G,MATCH($A39,'Ingredient Database'!$B:$B,0)),0)) -> 0 | E39: =IF($A39="",0,$B39*IFERROR(INDEX('Ingredient Database'!$E:$E,MATCH($A39,'Ingredient Database'!$B:$B,0)),0)) -> 0 | F39: =IF($A39="",0,$B39*IFERROR(INDEX('Ingredient Database'!$H:$H,MATCH($A39,'Ingredient Database'!$B:$B,0)),0)) -> 0
C40: =IF($A40="",0,$B40*IFERROR(INDEX('Ingredient Database'!$F:$F,MATCH($A40,'Ingredient Database'!$B:$B,0)),0)) -> 0 | D40: =IF($A40="",0,$B40*IFERROR(INDEX('Ingredient Database'!$G:$G,MATCH($A40,'Ingredient Database'!$B:$B,0)),0)) -> 0 | E40: =IF($A40="",0,$B40*IFERROR(INDEX('Ingredient Database'!$E:$E,MATCH($A40,'Ingredient Database'!$B:$B,0)),0)) -> 0 | F40: =IF($A40="",0,$B40*IFERROR(INDEX('Ingredient Database'!$H:$H,MATCH($A40,'Ingredient Database'!$B:$B,0)),0)) -> 0
C41: =IF($A41="",0,$B41*IFERROR(INDEX('Ingredient Database'!$F:$F,MATCH($A41,'Ingredient Database'!$B:$B,0)),0)) -> 0 | D41: =IF($A41="",0,$B41*IFERROR(INDEX('Ingredient Database'!$G:$G,MATCH($A41,'Ingredient Database'!$B:$B,0)),0)) -> 0 | E41: =IF($A41="",0,$B41*IFERROR(INDEX('Ingredient Database'!$E:$E,MATCH($A41,'Ingredient Database'!$B:$B,0)),0)) -> 0 | F41: =IF($A41="",0,$B41*IFERROR(INDEX('Ingredient Database'!$H:$H,MATCH($A41,'Ingredient Database'!$B:$B,0)),0)) -> 0
A42: TOTAL | B42: =SUM(B36:B41) -> 1 | C42: =SUM(C36:C41) -> 0.066 | D42: =SUM(D36:D41) -> 0.589 | E42: =SUM(E36:E41) -> 0.523 | F42: =SUM(F36:F41) -> 1.85257
A44: Phase 3 - Finishing
A45: Ingredient (dropdown) | B45: % of Total Roughage | C45: CP Contribution | D45: TDN Contribution | E45: DM Contribution | F45: Energy Contribution (Mcal)
...

Sheet Animal Register
A1: ANIMAL REGISTER
A2: Ek hi register — Purpose column se Fattening/Qurbani/Dairy/Breeding Stock decide hota hai. Apna tag-number convention (jaise MB66, MC217) Animal ID mein use kar sakte hain.
A4: Animal ID | B4: Purpose | C4: Breed | D4: Sex | E4: Source | F4: Date of Birth / Acquired | G4: Sire ID | H4: Dam ID | I4: Acquisition / Birth Weight (kg) | J4: Acquisition Cost (Rs) | K4: Program Start Date | L4: Program Duration (days) | M4: Target ADG (g/day) | N4: Program End Date | O4: Days on Feed | P4: Current Phase | Q4: Status | R4: Notes | S4: Current Weight (kg) | T4: Gain So Far (kg) | U4: Qurbani Rank | V4: Dairy Rank | W4: Breeding Rank
A5: A-01 | B5: Fattening | C5: Mix Breed | D5: Male | E5: Purchased - Mandi | F5: 46240 | I5: 212 | J5: 48000 | K5: 46240 | L5: 100 | M5: 1150 | N5: =IF(OR($K5="",$L5=""),"",$K5+$L5) -> 46340 | O5: =IF(OR($K5="",$L5=""),"",IF($Q5="Sold",$L5,MIN($L5,MAX(0,TODAY()-$K5)))) -> 9 | P5: =IF(OR($K5="",$L5=""),"",IF(O5<=$L5*0.33,"Phase 1 - Adaptation",IF(O5<=$L5*0.66,"Phase 2 - Growth","Phase 3 - Finishing"))) -> Phase 1 - Adaptation | Q5: Active | R5: Example row - apna data yahan se neeche likhna shuru karein | S5: =IF($A5="","",IF(SUMPRODUCT(MAX(('Weight Log'!$A$5:$A$154=$A5)*('Weight Log'!$C$5:$C$154)))=0,$I5,SUMPRODUCT(MAX(('Weight Log'!$A$5:$A$154=$A5)*('Weight Log'!$C$5:$C$154))))) -> 212 | T5: =IF($A5="","",S5-I5) -> 0 | U5: =IF($B5="Qurbani",COUNTIF($B$5:$B5,"Qurbani"),"") | V5: =IF($B5="Dairy",COUNTIF($B$5:$B5,"Dairy"),"") | W5: =IF($B5="Breeding Stock",COUNTIF($B$5:$B5,"Breeding Stock"),"")
N6: =IF(OR($K6="",$L6=""),"",$K6+$L6) | O6: =IF(OR($K6="",$L6=""),"",IF($Q6="Sold",$L6,MIN($L6,MAX(0,TODAY()-$K6)))) | P6: =IF(OR($K6="",$L6=""),"",IF(O6<=$L6*0.33,"Phase 1 - Adaptation",IF(O6<=$L6*0.66,"Phase 2 - Growth","Phase 3 - Finishing"))) | S6: =IF($A6="","",IF(SUMPRODUCT(MAX(('Weight Log'!$A$5:$A$154=$A6)*('Weight Log'!$C$5:$C$154)))=0,$I6,SUMPRODUCT(MAX(('Weight Log'!$A$5:$A$154=$A6)*('Weight Log'!$C$5:$C$154))))) | T6: =IF($A6="","",S6-I6) | U6: =IF($B6="Qurbani",COUNTIF($B$5:$B6,"Qurbani"),"") | V6: =IF($B6="Dairy",COUNTIF($B$5:$B6,"Dairy"),"") | W6: =IF($B6="Breeding Stock",COUNTIF($B$5:$B6,"Breeding Stock"),"")
N7: =IF(OR($K7="",$L7=""),"",$K7+$L7) | O7: =IF(OR($K7="",$L7=""),"",IF($Q7="Sold",$L7,MIN($L7,MAX(0,TODAY()-$K7)))) | P7: =IF(OR($K7="",$L7=""),"",IF(O7<=$L7*0.33,"Phase 1 - Adaptation",IF(O7<=$L7*0.66,"Phase 2 - Growth","Phase 3 - Finishing"))) | S7: =IF($A7="","",IF(SUMPRODUCT(MAX(('Weight Log'!$A$5:$A$154=$A7)*('Weight Log'!$C$5:$C$154)))=0,$I7,SUMPRODUCT(MAX(('Weight Log'!$A$5:$A$154=$A7)*('Weight Log'!$C$5:$C$154))))) | T7: =IF($A7="","",S7-I7) | U7: =IF($B7="Qurbani",COUNTIF($B$5:$B7,"Qurbani"),"") | V7: =IF($B7="Dairy",COUNTIF($B$5:$B7,"Dairy"),"") | W7: =IF($B7="Breeding Stock",COUNTIF($B$5:$B7,"Breeding Stock"),"")
N8: =IF(OR($K8="",$L8=""),"",$K8+$L8) | O8: =IF(OR($K8="",$L8=""),"",IF($Q8="Sold",$L8,MIN($L8,MAX(0,TODAY()-$K8)))) | P8: =IF(OR($K8="",$L8=""),"",IF(O8<=$L8*0.33,"Phase 1 - Adaptation",IF(O8<=$L8*0.66,"Phase 2 - Growth","Phase 3 - Finishing"))) | S8: =IF($A8="","",IF(SUMPRODUCT(MAX(('Weight Log'!$A$5:$A$154=$A8)*('Weight Log'!$C$5:$C$154)))=0,$I8,SUMPRODUCT(MAX(('Weight Log'!$A$5:$A$154=$A8)*('Weight Log'!$C$5:$C$154))))) | T8: =IF($A8="","",S8-I8) | U8: =IF($B8="Qurbani",COUNTIF($B$5:$B8,"Qurbani"),"") | V8: =IF($B8="Dairy",COUNTIF($B$5:$B8,"Dairy"),"") | W8: =IF($B8="Breeding Stock",COUNTIF($B$5:$B8,"Breeding Stock"),"")
N9: =IF(OR($K9="",$L9=""),"",$K9+$L9) | O9: =IF(OR($K9="",$L9=""),"",IF($Q9="Sold",$L9,MIN($L9,MAX(0,TODAY()-$K9)))) | P9: =IF(OR($K9="",$L9=""),"",IF(O9<=$L9*0.33,"Phase 1 - Adaptation",IF(O9<=$L9*0.66,"Phase 2 - Growth","Phase 3 - Finishing"))) | S9: =IF($A9="","",IF(SUMPRODUCT(MAX(('Weight Log'!$A$5:$A$154=$A9)*('Weight Log'!$C$5:$C$154)))=0,$I9,SUMPRODUCT(MAX(('Weight Log'!$A$5:$A$154=$A9)*('Weight Log'!$C$5:$C$154))))) | T9: =IF($A9="","",S9-I9) | U9: =IF($B9="Qurbani",COUNTIF($B$5:$B9,"Qurbani"),"") | V9: =IF($B9="Dairy",COUNTIF($B$5:$B9,"Dairy"),"") | W9: =IF($B9="Breeding Stock",COUNTIF($B$5:$B9,"Breeding Stock"),"")
N10: =IF(OR($K10="",$L10=""),"",$K10+$L10) | O10: =IF(OR($K10="",$L10=""),"",IF($Q10="Sold",$L10,MIN($L10,MAX(0,TODAY()-$K10)))) | P10: =IF(OR($K10="",$L10=""),"",IF(O10<=$L10*0.33,"Phase 1 - Adaptation",IF(O10<=$L10*0.66,"Phase 2 - Growth","Phase 3 - Finishing"))) | S10: =IF($A10="","",IF(SUMPRODUCT(MAX(('Weight Log'!$A$5:$A$154=$A10)*('Weight Log'!$C$5:$C$154)))=0,$I10,SUMPRODUCT(MAX(('Weight Log'!$A$5:$A$154=$A10)*('Weight Log'!$C$5:$C$154))))) | T10: =IF($A10="","",S10-I10) | U10: =IF($B10="Qurbani",COUNTIF($B$5:$B10,"Qurbani"),"") | V10: =IF($B10="Dairy",COUNTIF($B$5:$B10,"Dairy"),"") | W10: =IF($B10="Breeding Stock",COUNTIF($B$5:$B10,"Breeding Stock"),"")
N11: =IF(OR($K11="",$L11=""),"",$K11+$L11) | O11: =IF(OR($K11="",$L11=""),"",IF($Q11="Sold",$L11,MIN($L11,MAX(0,TODAY()-$K11)))) | P11: =IF(OR($K11="",$L11=""),"",IF(O11<=$L11*0.33,"Phase 1 - Adaptation",IF(O11<=$L11*0.66,"Phase 2 - Growth","Phase 3 - Finishing"))) | S11: =IF($A11="","",IF(SUMPRODUCT(MAX(('Weight Log'!$A$5:$A$154=$A11)*('Weight Log'!$C$5:$C$154)))=0,$I11,SUMPRODUCT(MAX(('Weight Log'!$A$5:$A$154=$A11)*('Weight Log'!$C$5:$C$154))))) | T11: =IF($A11="","",S11-I11) | U11: =IF($B11="Qurbani",COUNTIF($B$5:$B11,"Qurbani"),"") | V11: =IF($B11="Dairy",COUNTIF($B$5:$B11,"Dairy"),"") | W11: =IF($B11="Breeding Stock",COUNTIF($B$5:$B11,"Breeding Stock"),"")
N12: =IF(OR($K12="",$L12=""),"",$K12+$L12) | O12: =IF(OR($K12="",$L12=""),"",IF($Q12="Sold",$L12,MIN($L12,MAX(0,TODAY()-$K12)))) | P12: =IF(OR($K12="",$L12=""),"",IF(O12<=$L12*0.33,"Phase 1 - Adaptation",IF(O12<=$L12*0.66,"Phase 2 - Growth","Phase 3 - Finishing"))) | S12: =IF($A12="","",IF(SUMPRODUCT(MAX(('Weight Log'!$A$5:$A$154=$A12)*('Weight Log'!$C$5:$C$154)))=0,$I12,SUMPRODUCT(MAX(('Weight Log'!$A$5:$A$154=$A12)*('Weight Log'!$C$5:$C$154))))) | T12: =IF($A12="","",S12-I12) | U12: =IF($B12="Qurbani",COUNTIF($B$5:$B12,"Qurbani"),"") | V12: =IF($B12="Dairy",COUNTIF($B$5:$B12,"Dairy"),"") | W12: =IF($B12="Breeding Stock",COUNTIF($B$5:$B12,"Breeding Stock"),"")
N13: =IF(OR($K13="",$L13=""),"",$K13+$L13) | O13: =IF(OR($K13="",$L13=""),"",IF($Q13="Sold",$L13,MIN($L13,MAX(0,TODAY()-$K13)))) | P13: =IF(OR($K13="",$L13=""),"",IF(O13<=$L13*0.33,"Phase 1 - Adaptation",IF(O13<=$L13*0.66,"Phase 2 - Growth","Phase 3 - Finishing"))) | S13: =IF($A13="","",IF(SUMPRODUCT(MAX(('Weight Log'!$A$5:$A$154=$A13)*('Weight Log'!$C$5:$C$154)))=0,$I13,SUMPRODUCT(MAX(('Weight Log'!$A$5:$A$154=$A13)*('Weight Log'!$C$5:$C$154))))) | T13: =IF($A13="","",S13-I13) | U13: =IF($B13="Qurbani",COUNTIF($B$5:$B13,"Qurbani"),"") | V13: =IF($B13="Dairy",COUNTIF($B$5:$B13,"Dairy"),"") | W13: =IF($B13="Breeding Stock",COUNTIF($B$5:$B13,"Breeding Stock"),"")
N14: =IF(OR($K14="",$L14=""),"",$K14+$L14) | O14: =IF(OR($K14="",$L14=""),"",IF($Q14="Sold",$L14,MIN($L14,MAX(0,TODAY()-$K14)))) | P14: =IF(OR($K14="",$L14=""),"",IF(O14<=$L14*0.33,"Phase 1 - Adaptation",IF(O14<=$L14*0.66,"Phase 2 - Growth","Phase 3 - Finishing"))) | S14: =IF($A14="","",IF(SUMPRODUCT(MAX(('Weight Log'!$A$5:$A$154=$A14)*('Weight Log'!$C$5:$C$154)))=0,$I14,SUMPRODUCT(MAX(('Weight Log'!$A$5:$A$154=$A14)*('Weight Log'!$C$5:$C$154))))) | T14: =IF($A14="","",S14-I14) | U14: =IF($B14="Qurbani",COUNTIF($B$5:$B14,"Qurbani"),"") | V14: =IF($B14="Dairy",COUNTIF($B$5:$B14,"Dairy"),"") | W14: =IF($B14="Breeding Stock",COUNTIF($B$5:$B14,"Breeding Stock"),"")
N15: =IF(OR($K15="",$L15=""),"",$K15+$L15) | O15: =IF(OR($K15="",$L15=""),"",IF($Q15="Sold",$L15,MIN($L15,MAX(0,TODAY()-$K15)))) | P15: =IF(OR($K15="",$L15=""),"",IF(O15<=$L15*0.33,"Phase 1 - Adaptation",IF(O15<=$L15*0.66,"Phase 2 - Growth","Phase 3 - Finishing"))) | S15: =IF($A15="","",IF(SUMPRODUCT(MAX(('Weight Log'!$A$5:$A$154=$A15)*('Weight Log'!$C$5:$C$154)))=0,$I15,SUMPRODUCT(MAX(('Weight Log'!$A$5:$A$154=$A15)*('Weight Log'!$C$5:$C$154))))) | T15: =IF($A15="","",S15-I15) | U15: =IF($B15="Qurbani",COUNTIF($B$5:$B15,"Qurbani"),"") | V15: =IF($B15="Dairy",COUNTIF($B$5:$B15,"Dairy"),"") | W15: =IF($B15="Breeding Stock",COUNTIF($B$5:$B15,"Breeding Stock"),"")
N16: =IF(OR($K16="",$L16=""),"",$K16+$L16) | O16: =IF(OR($K16="",$L16=""),"",IF($Q16="Sold",$L16,MIN($L16,MAX(0,TODAY()-$K16)))) | P16: =IF(OR($K16="",$L16=""),"",IF(O16<=$L16*0.33,"Phase 1 - Adaptation",IF(O16<=$L16*0.66,"Phase 2 - Growth","Phase 3 - Finishing"))) | S16: =IF($A16="","",IF(SUMPRODUCT(MAX(('Weight Log'!$A$5:$A$154=$A16)*('Weight Log'!$C$5:$C$154)))=0,$I16,SUMPRODUCT(MAX(('Weight Log'!$A$5:$A$154=$A16)*('Weight Log'!$C$5:$C$154))))) | T16: =IF($A16="","",S16-I16) | U16: =IF($B16="Qurbani",COUNTIF($B$5:$B16,"Qurbani"),"") | V16: =IF($B16="Dairy",COUNTIF($B$5:$B16,"Dairy"),"") | W16: =IF($B16="Breeding Stock",COUNTIF($B$5:$B16,"Breeding Stock"),"")
N17: =IF(OR($K17="",$L17=""),"",$K17+$L17) | O17: =IF(OR($K17="",$L17=""),"",IF($Q17="Sold",$L17,MIN($L17,MAX(0,TODAY()-$K17)))) | P17: =IF(OR($K17="",$L17=""),"",IF(O17<=$L17*0.33,"Phase 1 - Adaptation",IF(O17<=$L17*0.66,"Phase 2 - Growth","Phase 3 - Finishing"))) | S17: =IF($A17="","",IF(SUMPRODUCT(MAX(('Weight Log'!$A$5:$A$154=$A17)*('Weight Log'!$C$5:$C$154)))=0,$I17,SUMPRODUCT(MAX(('Weight Log'!$A$5:$A$154=$A17)*('Weight Log'!$C$5:$C$154))))) | T17: =IF($A17="","",S17-I17) | U17: =IF($B17="Qurbani",COUNTIF($B$5:$B17,"Qurbani"),"") | V17: =IF($B17="Dairy",COUNTIF($B$5:$B17,"Dairy"),"") | W17: =IF($B17="Breeding Stock",COUNTIF($B$5:$B17,"Breeding Stock"),"")
... N74: =IF(OR($K74="",$L74=""),"",$K74+$L74) | O74: =IF(OR($K74="",$L74=""),"",IF($Q74="Sold",$L74,MIN($L74,MAX(0,TODAY()-$K74)))) | P74: =IF(OR($K74="",$L74=""),"",IF(O74<=$L74*0.33,"Phase 1 - Adaptation",IF(O74<=$L74*0.66,"Phase 2 - Growth","Phase 3 - Finishing"))) | S74: =IF($A74="","",IF(SUMPRODUCT(MAX(('Weight Log'!$A$5:$A$154=$A74)*('Weight Log'!$C$5:$C$154)))=0,$I74,SUMPRODUCT(MAX(('Weight Log'!$A$5:$A$154=$A74)*('Weight Log'!$C$5:$C$154))))) | T74: =IF($A74="","",S74-I74) | U74: =IF($B74="Qurbani",COUNTIF($B$5:$B74,"Qurbani"),"") | V74: =IF($B74="Dairy",COUNTIF($B$5:$B74,"Dairy"),"") | W74: =IF($B74="Breeding Stock",COUNTIF($B$5:$B74,"Breeding Stock"),"")

Sheet Animal Profile
A1: ANIMAL PROFILE
A2: Neeche dropdown se Animal ID chunein — is animal ka poora record khud aa jayega.
A4: Select Animal ID: | B4: A-01
A6: BASIC INFO
A7: Purpose | B7: =IF($B$4="","",IFERROR(INDEX('Animal Register'!$B:$B,MATCH($B$4,'Animal Register'!$A:$A,0)),"-")) -> Fattening
A8: Breed | B8: =IF($B$4="","",IFERROR(INDEX('Animal Register'!$C:$C,MATCH($B$4,'Animal Register'!$A:$A,0)),"-")) -> Mix Breed
A9: Sex | B9: =IF($B$4="","",IFERROR(INDEX('Animal Register'!$D:$D,MATCH($B$4,'Animal Register'!$A:$A,0)),"-")) -> Male
A10: Source | B10: =IF($B$4="","",IFERROR(INDEX('Animal Register'!$E:$E,MATCH($B$4,'Animal Register'!$A:$A,0)),"-")) -> Purchased - Mandi
A11: Date of Birth / Acquired | B11: =IF($B$4="","",IFERROR(INDEX('Animal Register'!$F:$F,MATCH($B$4,'Animal Register'!$A:$A,0)),"-")) -> 46240
A12: Sire ID | B12: =IF($B$4="","",IF(IFERROR(INDEX('Animal Register'!$G:$G,MATCH($B$4,'Animal Register'!$A:$A,0)),"")="","-",INDEX('Animal Register'!$G:$G,MATCH($B$4,'Animal Register'!$A:$A,0)))) -> -
A13: Dam ID | B13: =IF($B$4="","",IF(IFERROR(INDEX('Animal Register'!$H:$H,MATCH($B$4,'Animal Register'!$A:$A,0)),"")="","-",INDEX('Animal Register'!$H:$H,MATCH($B$4,'Animal Register'!$A:$A,0)))) -> -
A14: Acquisition Cost (Rs) | B14: =IF($B$4="","",IFERROR(INDEX('Animal Register'!$J:$J,MATCH($B$4,'Animal Register'!$A:$A,0)),"-")) -> 48000
A15: Status | B15: =IF($B$4="","",IFERROR(INDEX('Animal Register'!$Q:$Q,MATCH($B$4,'Animal Register'!$A:$A,0)),"-")) -> Active
A16: Notes | B16: =IF($B$4="","",IFERROR(INDEX('Animal Register'!$R:$R,MATCH($B$4,'Animal Register'!$A:$A,0)),"-")) -> Example row - apna data yahan se neeche likhna shuru karein
A18: FATTENING / QURBANI PROGRAM (Dairy/Breeding Stock ke liye khali rahega)
A19: Program Start Date | B19: =IF($B$4="","",IFERROR(INDEX('Animal Register'!$K:$K,MATCH($B$4,'Animal Register'!$A:$A,0)),"-")) -> 46240
A20: Program Duration (days) | B20: =IF($B$4="","",IFERROR(INDEX('Animal Register'!$L:$L,MATCH($B$4,'Animal Register'!$A:$A,0)),"-")) -> 100
A21: Program End Date | B21: =IF($B$4="","",IFERROR(INDEX('Animal Register'!$N:$N,MATCH($B$4,'Animal Register'!$A:$A,0)),"-")) -> 46340
A22: Days on Feed | B22: =IF($B$4="","",IFERROR(INDEX('Animal Register'!$O:$O,MATCH($B$4,'Animal Register'!$A:$A,0)),"-")) -> 9
A23: Current Phase | B23: =IF($B$4="","",IFERROR(INDEX('Animal Register'!$P:$P,MATCH($B$4,'Animal Register'!$A:$A,0)),"-")) -> Phase 1 - Adaptation
A25: WEIGHT SUMMARY
A26: Acquisition / Birth Weight (kg) | B26: =IF($B$4="","",IFERROR(INDEX('Animal Register'!$I:$I,MATCH($B$4,'Animal Register'!$A:$A,0)),"-")) -> 212
A27: Current Weight (kg) | B27: =IF($B$4="","",IFERROR(INDEX('Animal Register'!$S:$S,MATCH($B$4,'Animal Register'!$A:$A,0)),"-")) -> 212
A28: Total Gain (kg) | B28: =IF($B$4="","",IFERROR(INDEX('Animal Register'!$T:$T,MATCH($B$4,'Animal Register'!$A:$A,0)),"-")) -> 0
A29: Target ADG (g/day) | B29: =IF($B$4="","",IFERROR(INDEX('Animal Register'!$M:$M,MATCH($B$4,'Animal Register'!$A:$A,0)),"-")) -> 1150
A30: Overall ADG (g/day) | B30: =IF($B$4="","",IFERROR(INDEX('Weight & Growth Tracker'!$J:$J,MATCH($B$4,'Weight & Growth Tracker'!$A:$A,0)),"-")) -> 0
A31: Last Weighing Date | B31: =IF($B$4="","",IFERROR(INDEX('Weight & Growth Tracker'!$F:$F,MATCH($B$4,'Weight & Growth Tracker'!$A:$A,0)),"-")) -> 46240
A32: Latest BCS | B32: =IF($B$4="","",IFERROR(INDEX('Weight & Growth Tracker'!$G:$G,MATCH($B$4,'Weight & Growth Tracker'!$A:$A,0)),"-")) -> 2.5
A33: Growth Status | B33: =IF($B$4="","",IFERROR(INDEX('Weight & Growth Tracker'!$L:$L,MATCH($B$4,'Weight & Growth Tracker'!$A:$A,0)),"-")) -> Behind Target
A35: FEEDING SUMMARY
A36: Total Days Fed (entries logged) | B36: =IF($B$4="","",COUNTIF('Daily Feeding'!$B:$B,$B$4)) -> 1
A37: Total DM Feed Consumed (kg) | B37: =IF($B$4="","",ROUND(SUMIF('Daily Feeding'!$B:$B,$B$4,'Daily Feeding'!$I:$I)+SUMIF('Daily Feeding'!$B:$B,$B$4,'Daily Feeding'!$J:$J),1)) -> 6.4
A38: Avg Daily Energy Intake (Mcal) | B38: =IF($B$4="","",IFERROR(ROUND(AVERAGEIF('Daily Feeding'!$B:$B,$B$4,'Daily Feeding'!$M:$M),2),"-")) -> 13.04
A39: Total Feed Cost - this animal (Rs) | B39: =IF($B$4="","",ROUND(SUMIF('Cost Tracker'!$B:$B,$B$4,'Cost Tracker'!$F:$F),0)) -> 0
A41: HEALTH SUMMARY
A42: Total Treatments (count) | B42: =IF($B$4="","",COUNTIF('Health Log'!$A:$A,$B$4)) -> 1
A43: Last Treatment Date | B43: =IF($B$4="","",IF(SUMPRODUCT(MAX(('Health Log'!$A$4:$A$103=$B$4)*ROW('Health Log'!$A$4:$A$103)))=0,"-",INDEX('Health Log'!$B:$B,SUMPRODUCT(MAX(('Health Log'!$A$4:$A$103=$B$4)*ROW('Health Log'!$A$4:$A$103)))))) -> 46240
A44: Last Treatment Type | B44: =IF($B$4="","",IF(SUMPRODUCT(MAX(('Health Log'!$A$4:$A$103=$B$4)*ROW('Health Log'!$A$4:$A$103)))=0,"-",INDEX('Health Log'!$C:$C,SUMPRODUCT(MAX(('Health Log'!$A$4:$A$103=$B$4)*ROW('Health Log'!$A$4:$A$103)))))) -> Deworming
A45: Last Product / Medicine Used | B45: =IF($B$4="","",IF(SUMPRODUCT(MAX(('Health Log'!$A$4:$A$103=$B$4)*ROW('Health Log'!$A$4:$A$103)))=0,"-",INDEX('Health Log'!$D:$D,SUMPRODUCT(MAX(('Health Log'!$A$4:$A$103=$B$4)*ROW('Health Log'!$A$4:$A$103)))))) -> Example - apna medicine naam likhein
A46: Overdue Reminders (count) | B46: =IF($B$4="","",COUNTIFS('Health Log'!$A:$A,$B$4,'Health Log'!$F:$F,"<>",'Health Log'!$F:$F,"<"&TODAY())) -> 0

Sheet Qurbani Module
A1: QURBANI MODULE
A2: Animal Register mein jo bhi Purpose='Qurbani' likha jayega, wo yahan khud aa jayega. Naye Qurbani animals hamesha Animal Register ke aakhir mein add karein (beech mein insert na karein).
Q3: SALE / INVOICE LOG (yahan input karein)
A4: Animal ID | B4: Breed | C4: Purchase Date | D4: Purchase Weight (kg) | E4: Purchase Cost (Rs) | F4: Current Weight (kg) | G4: Days on Feed | H4: Target Sale Date | I4: Current Phase | J4: Sale Date | K4: Sale Weight (kg) | L4: Sale Price (Rs) | M4: Invoice No. | N4: Profit / Loss (Rs) | Q4: Animal ID | R4: Sale Date | S4: Sale Weight (kg) | T4: Sale Price (Rs) | U4: Invoice No.
A5: =IFERROR(INDEX('Animal Register'!$A:$A,MATCH(1,'Animal Register'!$U:$U,0)),"") | B5: =IF($A5="","",INDEX('Animal Register'!$C:$C,MATCH($A5,'Animal Register'!$A:$A,0))) | C5: =IF($A5="","",INDEX('Animal Register'!$K:$K,MATCH($A5,'Animal Register'!$A:$A,0))) | D5: =IF($A5="","",INDEX('Animal Register'!$I:$I,MATCH($A5,'Animal Register'!$A:$A,0))) | E5: =IF($A5="","",INDEX('Animal Register'!$J:$J,MATCH($A5,'Animal Register'!$A:$A,0))) | F5: =IF($A5="","",INDEX('Animal Register'!$S:$S,MATCH($A5,'Animal Register'!$A:$A,0))) | G5: =IF($A5="","",INDEX('Animal Register'!$O:$O,MATCH($A5,'Animal Register'!$A:$A,0))) | H5: =IF($A5="","",INDEX('Animal Register'!$N:$N,MATCH($A5,'Animal Register'!$A:$A,0))) | I5: =IF($A5="","",INDEX('Animal Register'!$P:$P,MATCH($A5,'Animal Register'!$A:$A,0))) | J5: =IF($A5="","",IFERROR(INDEX($R$5:$R$104,MATCH($A5,$Q$5:$Q$104,0)),"-")) | K5: =IF($A5="","",IFERROR(INDEX($S$5:$S$104,MATCH($A5,$Q$5:$Q$104,0)),"-")) | L5: =IF($A5="","",IFERROR(INDEX($T$5:$T$104,MATCH($A5,$Q$5:$Q$104,0)),"-")) | M5: =IF($A5="","",IFERROR(INDEX($U$5:$U$104,MATCH($A5,$Q$5:$Q$104,0)),"-")) | N5: =IF($A5="","",IF(ISNUMBER(L5),L5-E5,"-"))
A6: =IFERROR(INDEX('Animal Register'!$A:$A,MATCH(2,'Animal Register'!$U:$U,0)),"") | B6: =IF($A6="","",INDEX('Animal Register'!$C:$C,MATCH($A6,'Animal Register'!$A:$A,0))) | C6: =IF($A6="","",INDEX('Animal Register'!$K:$K,MATCH($A6,'Animal Register'!$A:$A,0))) | D6: =IF($A6="","",INDEX('Animal Register'!$I:$I,MATCH($A6,'Animal Register'!$A:$A,0))) | E6: =IF($A6="","",INDEX('Animal Register'!$J:$J,MATCH($A6,'Animal Register'!$A:$A,0))) | F6: =IF($A6="","",INDEX('Animal Register'!$S:$S,MATCH($A6,'Animal Register'!$A:$A,0))) | G6: =IF($A6="","",INDEX('Animal Register'!$O:$O,MATCH($A6,'Animal Register'!$A:$A,0))) | H6: =IF($A6="","",INDEX('Animal Register'!$N:$N,MATCH($A6,'Animal Register'!$A:$A,0))) | I6: =IF($A6="","",INDEX('Animal Register'!$P:$P,MATCH($A6,'Animal Register'!$A:$A,0))) | J6: =IF($A6="","",IFERROR(INDEX($R$5:$R$104,MATCH($A6,$Q$5:$Q$104,0)),"-")) | K6: =IF($A6="","",IFERROR(INDEX($S$5:$S$104,MATCH($A6,$Q$5:$Q$104,0)),"-")) | L6: =IF($A6="","",IFERROR(INDEX($T$5:$T$104,MATCH($A6,$Q$5:$Q$104,0)),"-")) | M6: =IF($A6="","",IFERROR(INDEX($U$5:$U$104,MATCH($A6,$Q$5:$Q$104,0)),"-")) | N6: =IF($A6="","",IF(ISNUMBER(L6),L6-E6,"-"))
A7: =IFERROR(INDEX('Animal Register'!$A:$A,MATCH(3,'Animal Register'!$U:$U,0)),"") | B7: =IF($A7="","",INDEX('Animal Register'!$C:$C,MATCH($A7,'Animal Register'!$A:$A,0))) | C7: =IF($A7="","",INDEX('Animal Register'!$K:$K,MATCH($A7,'Animal Register'!$A:$A,0))) | D7: =IF($A7="","",INDEX('Animal Register'!$I:$I,MATCH($A7,'Animal Register'!$A:$A,0))) | E7: =IF($A7="","",INDEX('Animal Register'!$J:$J,MATCH($A7,'Animal Register'!$A:$A,0))) | F7: =IF($A7="","",INDEX('Animal Register'!$S:$S,MATCH($A7,'Animal Register'!$A:$A,0))) | G7: =IF($A7="","",INDEX('Animal Register'!$O:$O,MATCH($A7,'Animal Register'!$A:$A,0))) | H7: =IF($A7="","",INDEX('Animal Register'!$N:$N,MATCH($A7,'Animal Register'!$A:$A,0))) | I7: =IF($A7="","",INDEX('Animal Register'!$P:$P,MATCH($A7,'Animal Register'!$A:$A,0))) | J7: =IF($A7="","",IFERROR(INDEX($R$5:$R$104,MATCH($A7,$Q$5:$Q$104,0)),"-")) | K7: =IF($A7="","",IFERROR(INDEX($S$5:$S$104,MATCH($A7,$Q$5:$Q$104,0)),"-")) | L7: =IF($A7="","",IFERROR(INDEX($T$5:$T$104,MATCH($A7,$Q$5:$Q$104,0)),"-")) | M7: =IF($A7="","",IFERROR(INDEX($U$5:$U$104,MATCH($A7,$Q$5:$Q$104,0)),"-")) | N7: =IF($A7="","",IF(ISNUMBER(L7),L7-E7,"-"))
A8: =IFERROR(INDEX('Animal Register'!$A:$A,MATCH(4,'Animal Register'!$U:$U,0)),"") | B8: =IF($A8="","",INDEX('Animal Register'!$C:$C,MATCH($A8,'Animal Register'!$A:$A,0))) | C8: =IF($A8="","",INDEX('Animal Register'!$K:$K,MATCH($A8,'Animal Register'!$A:$A,0))) | D8: =IF($A8="","",INDEX('Animal Register'!$I:$I,MATCH($A8,'Animal Register'!$A:$A,0))) | E8: =IF($A8="","",INDEX('Animal Register'!$J:$J,MATCH($A8,'Animal Register'!$A:$A,0))) | F8: =IF($A8="","",INDEX('Animal Register'!$S:$S,MATCH($A8,'Animal Register'!$A:$A,0))) | G8: =IF($A8="","",INDEX('Animal Register'!$O:$O,MATCH($A8,'Animal Register'!$A:$A,0))) | H8: =IF($A8="","",INDEX('Animal Register'!$N:$N,MATCH($A8,'Animal Register'!$A:$A,0))) | I8: =IF($A8="","",INDEX('Animal Register'!$P:$P,MATCH($A8,'Animal Register'!$A:$A,0))) | J8: =IF($A8="","",IFERROR(INDEX($R$5:$R$104,MATCH($A8,$Q$5:$Q$104,0)),"-")) | K8: =IF($A8="","",IFERROR(INDEX($S$5:$S$104,MATCH($A8,$Q$5:$Q$104,0)),"-")) | L8: =IF($A8="","",IFERROR(INDEX($T$5:$T$104,MATCH($A8,$Q$5:$Q$104,0)),"-")) | M8: =IF($A8="","",IFERROR(INDEX($U$5:$U$104,MATCH($A8,$Q$5:$Q$104,0)),"-")) | N8: =IF($A8="","",IF(ISNUMBER(L8),L8-E8,"-"))
A9: =IFERROR(INDEX('Animal Register'!$A:$A,MATCH(5,'Animal Register'!$U:$U,0)),"") | B9: =IF($A9="","",INDEX('Animal Register'!$C:$C,MATCH($A9,'Animal Register'!$A:$A,0))) | C9: =IF($A9="","",INDEX('Animal Register'!$K:$K,MATCH($A9,'Animal Register'!$A:$A,0))) | D9: =IF($A9="","",INDEX('Animal Register'!$I:$I,MATCH($A9,'Animal Register'!$A:$A,0))) | E9: =IF($A9="","",INDEX('Animal Register'!$J:$J,MATCH($A9,'Animal Register'!$A:$A,0))) | F9: =IF($A9="","",INDEX('Animal Register'!$S:$S,MATCH($A9,'Animal Register'!$A:$A,0))) | G9: =IF($A9="","",INDEX('Animal Register'!$O:$O,MATCH($A9,'Animal Register'!$A:$A,0))) | H9: =IF($A9="","",INDEX('Animal Register'!$N:$N,MATCH($A9,'Animal Register'!$A:$A,0))) | I9: =IF($A9="","",INDEX('Animal Register'!$P:$P,MATCH($A9,'Animal Register'!$A:$A,0))) | J9: =IF($A9="","",IFERROR(INDEX($R$5:$R$104,MATCH($A9,$Q$5:$Q$104,0)),"-")) | K9: =IF($A9="","",IFERROR(INDEX($S$5:$S$104,MATCH($A9,$Q$5:$Q$104,0)),"-")) | L9: =IF($A9="","",IFERROR(INDEX($T$5:$T$104,MATCH($A9,$Q$5:$Q$104,0)),"-")) | M9: =IF($A9="","",IFERROR(INDEX($U$5:$U$104,MATCH($A9,$Q$5:$Q$104,0)),"-")) | N9: =IF($A9="","",IF(ISNUMBER(L9),L9-E9,"-"))
A10: =IFERROR(INDEX('Animal Register'!$A:$A,MATCH(6,'Animal Register'!$U:$U,0)),"") | B10: =IF($A10="","",INDEX('Animal Register'!$C:$C,MATCH($A10,'Animal Register'!$A:$A,0))) | C10: =IF($A10="","",INDEX('Animal Register'!$K:$K,MATCH($A10,'Animal Register'!$A:$A,0))) | D10: =IF($A10="","",INDEX('Animal Register'!$I:$I,MATCH($A10,'Animal Register'!$A:$A,0))) | E10: =IF($A10="","",INDEX('Animal Register'!$J:$J,MATCH($A10,'Animal Register'!$A:$A,0))) | F10: =IF($A10="","",INDEX('Animal Register'!$S:$S,MATCH($A10,'Animal Register'!$A:$A,0))) | G10: =IF($A10="","",INDEX('Animal Register'!$O:$O,MATCH($A10,'Animal Register'!$A:$A,0))) | H10: =IF($A10="","",INDEX('Animal Register'!$N:$N,MATCH($A10,'Animal Register'!$A:$A,0))) | I10: =IF($A10="","",INDEX('Animal Register'!$P:$P,MATCH($A10,'Animal Register'!$A:$A,0))) | J10: =IF($A10="","",IFERROR(INDEX($R$5:$R$104,MATCH($A10,$Q$5:$Q$104,0)),"-")) | K10: =IF($A10="","",IFERROR(INDEX($S$5:$S$104,MATCH($A10,$Q$5:$Q$104,0)),"-")) | L10: =IF($A10="","",IFERROR(INDEX($T$5:$T$104,MATCH($A10,$Q$5:$Q$104,0)),"-")) | M10: =IF($A10="","",IFERROR(INDEX($U$5:$U$104,MATCH($A10,$Q$5:$Q$104,0)),"-")) | N10: =IF($A10="","",IF(ISNUMBER(L10),L10-E10,"-"))
A11: =IFERROR(INDEX('Animal Register'!$A:$A,MATCH(7,'Animal Register'!$U:$U,0)),"") | B11: =IF($A11="","",INDEX('Animal Register'!$C:$C,MATCH($A11,'Animal Register'!$A:$A,0))) | C11: =IF($A11="","",INDEX('Animal Register'!$K:$K,MATCH($A11,'Animal Register'!$A:$A,0))) | D11: =IF($A11="","",INDEX('Animal Register'!$I:$I,MATCH($A11,'Animal Register'!$A:$A,0))) | E11: =IF($A11="","",INDEX('Animal Register'!$J:$J,MATCH($A11,'Animal Register'!$A:$A,0))) | F11: =IF($A11="","",INDEX('Animal Register'!$S:$S,MATCH($A11,'Animal Register'!$A:$A,0))) | G11: =IF($A11="","",INDEX('Animal Register'!$O:$O,MATCH($A11,'Animal Register'!$A:$A,0))) | H11: =IF($A11="","",INDEX('Animal Register'!$N:$N,MATCH($A11,'Animal Register'!$A:$A,0))) | I11: =IF($A11="","",INDEX('Animal Register'!$P:$P,MATCH($A11,'Animal Register'!$A:$A,0))) | J11: =IF($A11="","",IFERROR(INDEX($R$5:$R$104,MATCH($A11,$Q$5:$Q$104,0)),"-")) | K11: =IF($A11="","",IFERROR(INDEX($S$5:$S$104,MATCH($A11,$Q$5:$Q$104,0)),"-")) | L11: =IF($A11="","",IFERROR(INDEX($T$5:$T$104,MATCH($A11,$Q$5:$Q$104,0)),"-")) | M11: =IF($A11="","",IFERROR(INDEX($U$5:$U$104,MATCH($A11,$Q$5:$Q$104,0)),"-")) | N11: =IF($A11="","",IF(ISNUMBER(L11),L11-E11,"-"))
A12: =IFERROR(INDEX('Animal Register'!$A:$A,MATCH(8,'Animal Register'!$U:$U,0)),"") | B12: =IF($A12="","",INDEX('Animal Register'!$C:$C,MATCH($A12,'Animal Register'!$A:$A,0))) | C12: =IF($A12="","",INDEX('Animal Register'!$K:$K,MATCH($A12,'Animal Register'!$A:$A,0))) | D12: =IF($A12="","",INDEX('Animal Register'!$I:$I,MATCH($A12,'Animal Register'!$A:$A,0))) | E12: =IF($A12="","",INDEX('Animal Register'!$J:$J,MATCH($A12,'Animal Register'!$A:$A,0))) | F12: =IF($A12="","",INDEX('Animal Register'!$S:$S,MATCH($A12,'Animal Register'!$A:$A,0))) | G12: =IF($A12="","",INDEX('Animal Register'!$O:$O,MATCH($A12,'Animal Register'!$A:$A,0))) | H12: =IF($A12="","",INDEX('Animal Register'!$N:$N,MATCH($A12,'Animal Register'!$A:$A,0))) | I12: =IF($A12="","",INDEX('Animal Register'!$P:$P,MATCH($A12,'Animal Register'!$A:$A,0))) | J12: =IF($A12="","",IFERROR(INDEX($R$5:$R$104,MATCH($A12,$Q$5:$Q$104,0)),"-")) | K12: =IF($A12="","",IFERROR(INDEX($S$5:$S$104,MATCH($A12,$Q$5:$Q$104,0)),"-")) | L12: =IF($A12="","",IFERROR(INDEX($T$5:$T$104,MATCH($A12,$Q$5:$Q$104,0)),"-")) | M12: =IF($A12="","",IFERROR(INDEX($U$5:$U$104,MATCH($A12,$Q$5:$Q$104,0)),"-")) | N12: =IF($A12="","",IF(ISNUMBER(L12),L12-E12,"-"))
A13: =IFERROR(INDEX('Animal Register'!$A:$A,MATCH(9,'Animal Register'!$U:$U,0)),"") | B13: =IF($A13="","",INDEX('Animal Register'!$C:$C,MATCH($A13,'Animal Register'!$A:$A,0))) | C13: =IF($A13="","",INDEX('Animal Register'!$K:$K,MATCH($A13,'Animal Register'!$A:$A,0))) | D13: =IF($A13="","",INDEX('Animal Register'!$I:$I,MATCH($A13,'Animal Register'!$A:$A,0))) | E13: =IF($A13="","",INDEX('Animal Register'!$J:$J,MATCH($A13,'Animal Register'!$A:$A,0))) | F13: =IF($A13="","",INDEX('Animal Register'!$S:$S,MATCH($A13,'Animal Register'!$A:$A,0))) | G13: =IF($A13="","",INDEX('Animal Register'!$O:$O,MATCH($A13,'Animal Register'!$A:$A,0))) | H13: =IF($A13="","",INDEX('Animal Register'!$N:$N,MATCH($A13,'Animal Register'!$A:$A,0))) | I13: =IF($A13="","",INDEX('Animal Register'!$P:$P,MATCH($A13,'Animal Register'!$A:$A,0))) | J13: =IF($A13="","",IFERROR(INDEX($R$5:$R$104,MATCH($A13,$Q$5:$Q$104,0)),"-")) | K13: =IF($A13="","",IFERROR(INDEX($S$5:$S$104,MATCH($A13,$Q$5:$Q$104,0)),"-")) | L13: =IF($A13="","",IFERROR(INDEX($T$5:$T$104,MATCH($A13,$Q$5:$Q$104,0)),"-")) | M13: =IF($A13="","",IFERROR(INDEX($U$5:$U$104,MATCH($A13,$Q$5:$Q$104,0)),"-")) | N13: =IF($A13="","",IF(ISNUMBER(L13),L13-E13,"-"))
A14: =IFERROR(INDEX('Animal Register'!$A:$A,MATCH(10,'Animal Register'!$U:$U,0)),"") | B14: =IF($A14="","",INDEX('Animal Register'!$C:$C,MATCH($A14,'Animal Register'!$A:$A,0))) | C14: =IF($A14="","",INDEX('Animal Register'!$K:$K,MATCH($A14,'Animal Register'!$A:$A,0))) | D14: =IF($A14="","",INDEX('Animal Register'!$I:$I,MATCH($A14,'Animal Register'!$A:$A,0))) | E14: =IF($A14="","",INDEX('Animal Register'!$J:$J,MATCH($A14,'Animal Register'!$A:$A,0))) | F14: =IF($A14="","",INDEX('Animal Register'!$S:$S,MATCH($A14,'Animal Register'!$A:$A,0))) | G14: =IF($A14="","",INDEX('Animal Register'!$O:$O,MATCH($A14,'Animal Register'!$A:$A,0))) | H14: =IF($A14="","",INDEX('Animal Register'!$N:$N,MATCH($A14,'Animal Register'!$A:$A,0))) | I14: =IF($A14="","",INDEX('Animal Register'!$P:$P,MATCH($A14,'Animal Register'!$A:$A,0))) | J14: =IF($A14="","",IFERROR(INDEX($R$5:$R$104,MATCH($A14,$Q$5:$Q$104,0)),"-")) | K14: =IF($A14="","",IFERROR(INDEX($S$5:$S$104,MATCH($A14,$Q$5:$Q$104,0)),"-")) | L14: =IF($A14="","",IFERROR(INDEX($T$5:$T$104,MATCH($A14,$Q$5:$Q$104,0)),"-")) | M14: =IF($A14="","",IFERROR(INDEX($U$5:$U$104,MATCH($A14,$Q$5:$Q$104,0)),"-")) | N14: =IF($A14="","",IF(ISNUMBER(L14),L14-E14,"-"))
A15: =IFERROR(INDEX('Animal Register'!$A:$A,MATCH(11,'Animal Register'!$U:$U,0)),"") | B15: =IF($A15="","",INDEX('Animal Register'!$C:$C,MATCH($A15,'Animal Register'!$A:$A,0))) | C15: =IF($A15="","",INDEX('Animal Register'!$K:$K,MATCH($A15,'Animal Register'!$A:$A,0))) | D15: =IF($A15="","",INDEX('Animal Register'!$I:$I,MATCH($A15,'Animal Register'!$A:$A,0))) | E15: =IF($A15="","",INDEX('Animal Register'!$J:$J,MATCH($A15,'Animal Register'!$A:$A,0))) | F15: =IF($A15="","",INDEX('Animal Register'!$S:$S,MATCH($A15,'Animal Register'!$A:$A,0))) | G15: =IF($A15="","",INDEX('Animal Register'!$O:$O,MATCH($A15,'Animal Register'!$A:$A,0))) | H15: =IF($A15="","",INDEX('Animal Register'!$N:$N,MATCH($A15,'Animal Register'!$A:$A,0))) | I15: =IF($A15="","",INDEX('Animal Register'!$P:$P,MATCH($A15,'Animal Register'!$A:$A,0))) | J15: =IF($A15="","",IFERROR(INDEX($R$5:$R$104,MATCH($A15,$Q$5:$Q$104,0)),"-")) | K15: =IF($A15="","",IFERROR(INDEX($S$5:$S$104,MATCH($A15,$Q$5:$Q$104,0)),"-")) | L15: =IF($A15="","",IFERROR(INDEX($T$5:$T$104,MATCH($A15,$Q$5:$Q$104,0)),"-")) | M15: =IF($A15="","",IFERROR(INDEX($U$5:$U$104,MATCH($A15,$Q$5:$Q$104,0)),"-")) | N15: =IF($A15="","",IF(ISNUMBER(L15),L15-E15,"-"))
A16: =IFERROR(INDEX('Animal Register'!$A:$A,MATCH(12,'Animal Register'!$U:$U,0)),"") | B16: =IF($A16="","",INDEX('Animal Register'!$C:$C,MATCH($A16,'Animal Register'!$A:$A,0))) | C16: =IF($A16="","",INDEX('Animal Register'!$K:$K,MATCH($A16,'Animal Register'!$A:$A,0))) | D16: =IF($A16="","",INDEX('Animal Register'!$I:$I,MATCH($A16,'Animal Register'!$A:$A,0))) | E16: =IF($A16="","",INDEX('Animal Register'!$J:$J,MATCH($A16,'Animal Register'!$A:$A,0))) | F16: =IF($A16="","",INDEX('Animal Register'!$S:$S,MATCH($A16,'Animal Register'!$A:$A,0))) | G16: =IF($A16="","",INDEX('Animal Register'!$O:$O,MATCH($A16,'Animal Register'!$A:$A,0))) | H16: =IF($A16="","",INDEX('Animal Register'!$N:$N,MATCH($A16,'Animal Register'!$A:$A,0))) | I16: =IF($A16="","",INDEX('Animal Register'!$P:$P,MATCH($A16,'Animal Register'!$A:$A,0))) | J16: =IF($A16="","",IFERROR(INDEX($R$5:$R$104,MATCH($A16,$Q$5:$Q$104,0)),"-")) | K16: =IF($A16="","",IFERROR(INDEX($S$5:$S$104,MATCH($A16,$Q$5:$Q$104,0)),"-")) | L16: =IF($A16="","",IFERROR(INDEX($T$5:$T$104,MATCH($A16,$Q$5:$Q$104,0)),"-")) | M16: =IF($A16="","",IFERROR(INDEX($U$5:$U$104,MATCH($A16,$Q$5:$Q$104,0)),"-")) | N16: =IF($A16="","",IF(ISNUMBER(L16),L16-E16,"-"))
A17: =IFERROR(INDEX('Animal Register'!$A:$A,MATCH(13,'Animal Register'!$U:$U,0)),"") | B17: =IF($A17="","",INDEX('Animal Register'!$C:$C,MATCH($A17,'Animal Register'!$A:$A,0))) | C17: =IF($A17="","",INDEX('Animal Register'!$K:$K,MATCH($A17,'Animal Register'!$A:$A,0))) | D17: =IF($A17="","",INDEX('Animal Register'!$I:$I,MATCH($A17,'Animal Register'!$A:$A,0))) | E17: =IF($A17="","",INDEX('Animal Register'!$J:$J,MATCH($A17,'Animal Register'!$A:$A,0))) | F17: =IF($A17="","",INDEX('Animal Register'!$S:$S,MATCH($A17,'Animal Register'!$A:$A,0))) | G17: =IF($A17="","",INDEX('Animal Register'!$O:$O,MATCH($A17,'Animal Register'!$A:$A,0))) | H17: =IF($A17="","",INDEX('Animal Register'!$N:$N,MATCH($A17,'Animal Register'!$A:$A,0))) | I17: =IF($A17="","",INDEX('Animal Register'!$P:$P,MATCH($A17,'Animal Register'!$A:$A,0))) | J17: =IF($A17="","",IFERROR(INDEX($R$5:$R$104,MATCH($A17,$Q$5:$Q$104,0)),"-")) | K17: =IF($A17="","",IFERROR(INDEX($S$5:$S$104,MATCH($A17,$Q$5:$Q$104,0)),"-")) | L17: =IF($A17="","",IFERROR(INDEX($T$5:$T$104,MATCH($A17,$Q$5:$Q$104,0)),"-")) | M17: =IF($A17="","",IFERROR(INDEX($U$5:$U$104,MATCH($A17,$Q$5:$Q$104,0)),"-")) | N17: =IF($A17="","",IF(ISNUMBER(L17),L17-E17,"-"))
A18: =IFERROR(INDEX('Animal Register'!$A:$A,MATCH(14,'Animal Register'!$U:$U,0)),"") | B18: =IF($A18="","",INDEX('Animal Register'!$C:$C,MATCH($A18,'Animal Register'!$A:$A,0))) | C18: =IF($A18="","",INDEX('Animal Register'!$K:$K,MATCH($A18,'Animal Register'!$A:$A,0))) | D18: =IF($A18="","",INDEX('Animal Register'!$I:$I,MATCH($A18,'Animal Register'!$A:$A,0))) | E18: =IF($A18="","",INDEX('Animal Register'!$J:$J,MATCH($A18,'Animal Register'!$A:$A,0))) | F18: =IF($A18="","",INDEX('Animal Register'!$S:$S,MATCH($A18,'Animal Register'!$A:$A,0))) | G18: =IF($A18="","",INDEX('Animal Register'!$O:$O,MATCH($A18,'Animal Register'!$A:$A,0))) | H18: =IF($A18="","",INDEX('Animal Register'!$N:$N,MATCH($A18,'Animal Register'!$A:$A,0))) | I18: =IF($A18="","",INDEX('Animal Register'!$P:$P,MATCH($A18,'Animal Register'!$A:$A,0))) | J18: =IF($A18="","",IFERROR(INDEX($R$5:$R$104,MATCH($A18,$Q$5:$Q$104,0)),"-")) | K18: =IF($A18="","",IFERROR(INDEX($S$5:$S$104,MATCH($A18,$Q$5:$Q$104,0)),"-")) | L18: =IF($A18="","",IFERROR(INDEX($T$5:$T$104,MATCH($A18,$Q$5:$Q$104,0)),"-")) | M18: =IF($A18="","",IFERROR(INDEX($U$5:$U$104,MATCH($A18,$Q$5:$Q$104,0)),"-")) | N18: =IF($A18="","",IF(ISNUMBER(L18),L18-E18,"-"))
A19: =IFERROR(INDEX('Animal Register'!$A:$A,MATCH(15,'Animal Register'!$U:$U,0)),"") | B19: =IF($A19="","",INDEX('Animal Register'!$C:$C,MATCH($A19,'Animal Register'!$A:$A,0))) | C19: =IF($A19="","",INDEX('Animal Register'!$K:$K,MATCH($A19,'Animal Register'!$A:$A,0))) | D19: =IF($A19="","",INDEX('Animal Register'!$I:$I,MATCH($A19,'Animal Register'!$A:$A,0))) | E19: =IF($A19="","",INDEX('Animal Register'!$J:$J,MATCH($A19,'Animal Register'!$A:$A,0))) | F19: =IF($A19="","",INDEX('Animal Register'!$S:$S,MATCH($A19,'Animal Register'!$A:$A,0))) | G19: =IF($A19="","",INDEX('Animal Register'!$O:$O,MATCH($A19,'Animal Register'!$A:$A,0))) | H19: =IF($A19="","",INDEX('Animal Register'!$N:$N,MATCH($A19,'Animal Register'!$A:$A,0))) | I19: =IF($A19="","",INDEX('Animal Register'!$P:$P,MATCH($A19,'Animal Register'!$A:$A,0))) | J19: =IF($A19="","",IFERROR(INDEX($R$5:$R$104,MATCH($A19,$Q$5:$Q$104,0)),"-")) | K19: =IF($A19="","",IFERROR(INDEX($S$5:$S$104,MATCH($A19,$Q$5:$Q$104,0)),"-")) | L19: =IF($A19="","",IFERROR(INDEX($T$5:$T$104,MATCH($A19,$Q$5:$Q$104,0)),"-")) | M19: =IF($A19="","",IFERROR(INDEX($U$5:$U$104,MATCH($A19,$Q$5:$Q$104,0)),"-")) | N19: =IF($A19="","",IF(ISNUMBER(L19),L19-E19,"-"))
A20: =IFERROR(INDEX('Animal Register'!$A:$A,MATCH(16,'Animal Register'!$U:$U,0)),"") | B20: =IF($A20="","",INDEX('Animal Register'!$C:$C,MATCH($A20,'Animal Register'!$A:$A,0))) | C20: =IF($A20="","",INDEX('Animal Register'!$K:$K,MATCH($A20,'Animal Register'!$A:$A,0))) | D20: =IF($A20="","",INDEX('Animal Register'!$I:$I,MATCH($A20,'Animal Register'!$A:$A,0))) | E20: =IF($A20="","",INDEX('Animal Register'!$J:$J,MATCH($A20,'Animal Register'!$A:$A,0))) | F20: =IF($A20="","",INDEX('Animal Register'!$S:$S,MATCH($A20,'Animal Register'!$A:$A,0))) | G20: =IF($A20="","",INDEX('Animal Register'!$O:$O,MATCH($A20,'Animal Register'!$A:$A,0))) | H20: =IF($A20="","",INDEX('Animal Register'!$N:$N,MATCH($A20,'Animal Register'!$A:$A,0))) | I20: =IF($A20="","",INDEX('Animal Register'!$P:$P,MATCH($A20,'Animal Register'!$A:$A,0))) | J20: =IF($A20="","",IFERROR(INDEX($R$5:$R$104,MATCH($A20,$Q$5:$Q$104,0)),"-")) | K20: =IF($A20="","",IFERROR(INDEX($S$5:$S$104,MATCH($A20,$Q$5:$Q$104,0)),"-")) | L20: =IF($A20="","",IFERROR(INDEX($T$5:$T$104,MATCH($A20,$Q$5:$Q$104,0)),"-")) | M20: =IF($A20="","",IFERROR(INDEX($U$5:$U$104,MATCH($A20,$Q$5:$Q$104,0)),"-")) | N20: =IF($A20="","",IF(ISNUMBER(L20),L20-E20,"-"))
A21: =IFERROR(INDEX('Animal Register'!$A:$A,MATCH(17,'Animal Register'!$U:$U,0)),"") | B21: =IF($A21="","",INDEX('Animal Register'!$C:$C,MATCH($A21,'Animal Register'!$A:$A,0))) | C21: =IF($A21="","",INDEX('Animal Register'!$K:$K,MATCH($A21,'Animal Register'!$A:$A,0))) | D21: =IF($A21="","",INDEX('Animal Register'!$I:$I,MATCH($A21,'Animal Register'!$A:$A,0))) | E21: =IF($A21="","",INDEX('Animal Register'!$J:$J,MATCH($A21,'Animal Register'!$A:$A,0))) | F21: =IF($A21="","",INDEX('Animal Register'!$S:$S,MATCH($A21,'Animal Register'!$A:$A,0))) | G21: =IF($A21="","",INDEX('Animal Register'!$O:$O,MATCH($A21,'Animal Register'!$A:$A,0))) | H21: =IF($A21="","",INDEX('Animal Register'!$N:$N,MATCH($A21,'Animal Register'!$A:$A,0))) | I21: =IF($A21="","",INDEX('Animal Register'!$P:$P,MATCH($A21,'Animal Register'!$A:$A,0))) | J21: =IF($A21="","",IFERROR(INDEX($R$5:$R$104,MATCH($A21,$Q$5:$Q$104,0)),"-")) | K21: =IF($A21="","",IFERROR(INDEX($S$5:$S$104,MATCH($A21,$Q$5:$Q$104,0)),"-")) | L21: =IF($A21="","",IFERROR(INDEX($T$5:$T$104,MATCH($A21,$Q$5:$Q$104,0)),"-")) | M21: =IF($A21="","",IFERROR(INDEX($U$5:$U$104,MATCH($A21,$Q$5:$Q$104,0)),"-")) | N21: =IF($A21="","",IF(ISNUMBER(L21),L21-E21,"-"))
A22: =IFERROR(INDEX('Animal Register'!$A:$A,MATCH(18,'Animal Register'!$U:$U,0)),"") | B22: =IF($A22="","",INDEX('Animal Register'!$C:$C,MATCH($A22,'Animal Register'!$A:$A,0))) | C22: =IF($A22="","",INDEX('Animal Register'!$K:$K,MATCH($A22,'Animal Register'!$A:$A,0))) | D22: =IF($A22="","",INDEX('Animal Register'!$I:$I,MATCH($A22,'Animal Register'!$A:$A,0))) | E22: =IF($A22="","",INDEX('Animal Register'!$J:$J,MATCH($A22,'Animal Register'!$A:$A,0))) | F22: =IF($A22="","",INDEX('Animal Register'!$S:$S,MATCH($A22,'Animal Register'!$A:$A,0))) | G22: =IF($A22="","",INDEX('Animal Register'!$O:$O,MATCH($A22,'Animal Register'!$A:$A,0))) | H22: =IF($A22="","",INDEX('Animal Register'!$N:$N,MATCH($A22,'Animal Register'!$A:$A,0))) | I22: =IF($A22="","",INDEX('Animal Register'!$P:$P,MATCH($A22,'Animal Register'!$A:$A,0))) | J22: =IF($A22="","",IFERROR(INDEX($R$5:$R$104,MATCH($A22,$Q$5:$Q$104,0)),"-")) | K22: =IF($A22="","",IFERROR(INDEX($S$5:$S$104,MATCH($A22,$Q$5:$Q$104,0)),"-")) | L22: =IF($A22="","",IFERROR(INDEX($T$5:$T$104,MATCH($A22,$Q$5:$Q$104,0)),"-")) | M22: =IF($A22="","",IFERROR(INDEX($U$5:$U$104,MATCH($A22,$Q$5:$Q$104,0)),"-")) | N22: =IF($A22="","",IF(ISNUMBER(L22),L22-E22,"-"))
A23: =IFERROR(INDEX('Animal Register'!$A:$A,MATCH(19,'Animal Register'!$U:$U,0)),"") | B23: =IF($A23="","",INDEX('Animal Register'!$C:$C,MATCH($A23,'Animal Register'!$A:$A,0))) | C23: =IF($A23="","",INDEX('Animal Register'!$K:$K,MATCH($A23,'Animal Register'!$A:$A,0))) | D23: =IF($A23="","",INDEX('Animal Register'!$I:$I,MATCH($A23,'Animal Register'!$A:$A,0))) | E23: =IF($A23="","",INDEX('Animal Register'!$J:$J,MATCH($A23,'Animal Register'!$A:$A,0))) | F23: =IF($A23="","",INDEX('Animal Register'!$S:$S,MATCH($A23,'Animal Register'!$A:$A,0))) | G23: =IF($A23="","",INDEX('Animal Register'!$O:$O,MATCH($A23,'Animal Register'!$A:$A,0))) | H23: =IF($A23="","",INDEX('Animal Register'!$N:$N,MATCH($A23,'Animal Register'!$A:$A,0))) | I23: =IF($A23="","",INDEX('Animal Register'!$P:$P,MATCH($A23,'Animal Register'!$A:$A,0))) | J23: =IF($A23="","",IFERROR(INDEX($R$5:$R$104,MATCH($A23,$Q$5:$Q$104,0)),"-")) | K23: =IF($A23="","",IFERROR(INDEX($S$5:$S$104,MATCH($A23,$Q$5:$Q$104,0)),"-")) | L23: =IF($A23="","",IFERROR(INDEX($T$5:$T$104,MATCH($A23,$Q$5:$Q$104,0)),"-")) | M23: =IF($A23="","",IFERROR(INDEX($U$5:$U$104,MATCH($A23,$Q$5:$Q$104,0)),"-")) | N23: =IF($A23="","",IF(ISNUMBER(L23),L23-E23,"-"))
